Workbook

Sheet Dashboard
B2: TED-Ed Channel Performance Analysis
B3: Age-adjusted outlier analysis · 93 long-form videos · last 12 months · snapshot 2026-09-28
B5: VIDEOS ANALYZED | E5: OUTLIERS (≥2x band median) | H5: UNDERPERFORMERS (≤0.5x) | K5: TOP CATEGORY (MEDIAN RATIO)
B6: =COUNTA(Data!A2:A94) -> 93 | E6: =COUNTIF(Data!M2:M94,"Outlier") -> 18 | H6: =COUNTIF(Data!M2:M94,"Underperformer") -> 13 | K6: =INDEX('Pivot Tables'!A6:A10,MATCH(MAX('Pivot Tables'!C6:C10),'Pivot Tables'!C6:C10,0)) -> Health/Psychology

Sheet Data
A1: Title | B1: Upload date | C1: Views | D1: Duration (sec) | E1: URL | F1: Date collected | G1: Is Short | H1: Age in days | I1: Views per day | J1: Age-band median | K1: Band median views | L1: Performance ratio | M1: Flag | N1: Title structure | O1: Topic category | P1: Everyday relevance | Q1: Is series (Think Like a Musician)
A2: Why magnets stumped scientists for so long - Rachel Yang | B2: 46289 | C2: 318509 | D2: 347 | E2: https://www.youtube.com/watch?v=jG7ULeWUfDw | F2: 46293 | G2: =FALSE() -> FALSE | H2: 4 | I2: 79627.25 | J2: 0-30 | K2: 638901.5 | L2: 0.49852599 | M2: Underperformer | N2: Statement | O2: Science | P2: No | Q2: =FALSE() -> FALSE
A3: 4 ways to fix your attention span - Shannon Odell | B3: 46287 | C3: 1609741 | D3: 326 | E3: https://www.youtube.com/watch?v=N2uQWfV6Jr4 | F3: 46293 | G3: =FALSE() -> FALSE | H3: 6 | I3: 268290.17 | J3: 0-30 | K3: 638901.5 | L3: 2.5195449 | M3: Outlier | N3: List | O3: Health/Psychology | P3: Yes | Q3: =FALSE() -> FALSE
A4: Everything you need to know about bird flu - Benjamin Anderson | B4: 46282 | C4: 418323 | D4: 390 | E4: https://www.youtube.com/watch?v=bHB5iiDDJ-s | F4: 46293 | G4: =FALSE() -> FALSE | H4: 11 | I4: 38029.364 | J4: 0-30 | K4: 638901.5 | L4: 0.65475351 | N4: Statement | O4: Health/Psychology | P4: No | Q4: =FALSE() -> FALSE
A5: How to explain something complicated | B5: 46280 | C5: 542871 | D5: 569 | E5: https://www.youtube.com/watch?v=EMbZ72cCAzI | F5: 46293 | G5: =FALSE() -> FALSE | H5: 13 | I5: 41759.308 | J5: 0-30 | K5: 638901.5 | L5: 0.84969436 | N5: Statement | O5: Society | P5: Yes | Q5: =FALSE() -> FALSE
A6: Why do some people have a better sense of direction than others? - Oliver Baumann | B6: 46275 | C6: 1506892 | D6: 354 | E6: https://www.youtube.com/watch?v=I8XaYkRW1tA | F6: 46293 | G6: =FALSE() -> FALSE | H6: 18 | I6: 83716.222 | J6: 0-30 | K6: 638901.5 | L6: 2.358567 | M6: Outlier | N6: Question | O6: Health/Psychology | P6: Yes | Q6: =FALSE() -> FALSE
A7: Ever walk into a room and forget what you were doing? - Gabriel Radvansky | B7: 46273 | C7: 734932 | D7: 345 | E7: https://www.youtube.com/watch?v=_gP3aXvNmv8 | F7: 46293 | G7: =FALSE() -> FALSE | H7: 20 | I7: 36746.6 | J7: 0-30 | K7: 638901.5 | L7: 1.1503056 | N7: Question | O7: Health/Psychology | P7: Yes | Q7: =FALSE() -> FALSE
A8: What are tariffs, and how do they work? | B8: 46268 | C8: 748587 | D8: 340 | E8: https://www.youtube.com/watch?v=BSdEiOYvKpE | F8: 46293 | G8: =FALSE() -> FALSE | H8: 25 | I8: 29943.48 | J8: 0-30 | K8: 638901.5 | L8: 1.1716783 | N8: Question | O8: Society | P8: No | Q8: =FALSE() -> FALSE
A9: 4 ways to tell a great story | B9: 46266 | C9: 522620 | D9: 306 | E9: https://www.youtube.com/watch?v=JOs-q7rXqdk | F9: 46293 | G9: =FALSE() -> FALSE | H9: 27 | I9: 19356.296 | J9: 0-30 | K9: 638901.5 | L9: 0.81799777 | N9: List | O9: Arts/Language | P9: Yes | Q9: =FALSE() -> FALSE
A10: Plato’s infamous Ship of State thought experiment - Michael Vazquez | B10: 46259 | C10: 498616 | D10: 340 | E10: https://www.youtube.com/watch?v=QyRqlTV60zM | F10: 46293 | G10: =FALSE() -> FALSE | H10: 34 | I10: 14665.176 | J10: 31-90 | K10: 351837 | L10: 1.417179 | N10: Statement | O10: History/Culture | P10: No | Q10: =FALSE() -> FALSE
A11: The tragedy of Cassandra, the princess who predicted the fall of Troy - Iseult Gillespie | B11: 46252 | C11: 214746 | D11: 280 | E11: https://www.youtube.com/watch?v=l29K-ZkARmE | F11: 46293 | G11: =FALSE() -> FALSE | H11: 41 | I11: 5237.7073 | J11: 31-90 | K11: 351837 | L11: 0.6103565 | N11: Statement | O11: History/Culture | P11: No | Q11: =FALSE() -> FALSE
A12: How do Maglev trains work? - Ning Zhao | B12: 46245 | C12: 310012 | D12: 388 | E12: https://www.youtube.com/watch?v=2A1IEBFt6Xg | F12: 46293 | G12: =FALSE() -> FALSE | H12: 48 | I12: 6458.5833 | J12: 31-90 | K12: 351837 | L12: 0.88112393 | N12: Question | O12: Science | P12: No | Q12: =FALSE() -> FALSE
A13: The fastest way to board a plane, according to mathematics - Rachel Yang | B13: 46238 | C13: 351837 | D13: 358 | E13: https://www.youtube.com/watch?v=-61qDRPG3to | F13: 46293 | G13: =FALSE() -> FALSE | H13: 55 | I13: 6397.0364 | J13: 31-90 | K13: 351837 | L13: 1 | N13: Statement | O13: Science | P13: Yes | Q13: =FALSE() -> FALSE
A14: Red gold: The world's most expensive spice - Carolyn Beans | B14: 46231 | C14: 288789 | D14: 401 | E14: https://www.youtube.com/watch?v=krNP8RlDsbw | F14: 46293 | G14: =FALSE() -> FALSE | H14: 62 | I14: 4657.8871 | J14: 31-90 | K14: 351837 | L14: 0.82080338 | N14: Statement | O14: History/Culture | P14: No | Q14: =FALSE() -> FALSE
A15: The magical forest realm hiding at the bottom of the ocean - Luka Seamus Wright and Salomé Buglass | B15: 46224 | C15: 141333 | D15: 351 | E15: https://www.youtube.com/watch?v=5jPCAlE0z7I | F15: 46293 | G15: =FALSE() -> FALSE | H15: 69 | I15: 2048.3043 | J15: 31-90 | K15: 351837 | L15: 0.40170022 | M15: Underperformer | N15: Statement | O15: Science | P15: No | Q15: =FALSE() -> FALSE
A16: When did we start using passports? - Kristin Surak | B16: 46217 | C16: 533755 | D16: 369 | E16: https://www.youtube.com/watch?v=JhxuP0AuRPA | F16: 46293 | G16: =FALSE() -> FALSE | H16: 76 | I16: 7023.0921 | J16: 31-90 | K16: 351837 | L16: 1.5170519 | N16: Question | O16: History/Culture | P16: No | Q16: =FALSE() -> FALSE
A17: How does the space station never run out of oxygen? - Alvaro Romero-Calvo and Theo St Francis | B17: 46210 | C17: 413731 | D17: 371 | E17: https://www.youtube.com/watch?v=5ljV0Vxu00M | F17: 46293 | G17: =FALSE() -> FALSE | H17: 83 | I17: 4984.7108 | J17: 31-90 | K17: 351837 | L17: 1.1759167 | N17: Question | O17: Science | P17: No | Q17: =FALSE() -> FALSE
A18: Psychedelics, mind control, radiation-eating: The secret superpowers of fungi - Max G. Levy | B18: 46203 | C18: 362764 | D18: 373 | E18: https://www.youtube.com/watch?v=QIqKGMM8ivM | F18: 46293 | G18: =FALSE() -> FALSE | H18: 90 | I18: 4030.7111 | J18: 31-90 | K18: 351837 | L18: 1.031057 | N18: Statement | O18: Science | P18: No | Q18: =FALSE() -> FALSE
A19: How a broken heart affects your body | B19: 46198 | C19: 369379 | D19: 318 | E19: https://www.youtube.com/watch?v=DbEZmLoGDbk | F19: 46293 | G19: =FALSE() -> FALSE | H19: 95 | I19: 3888.2 | J19: 91-180 | K19: 303633 | L19: 1.2165311 | N19: Statement | O19: Health/Psychology | P19: Yes | Q19: =FALSE() -> FALSE
A20: Why avalanches are most deadly when they stop - Simon Trautman | B20: 46196 | C20: 212241 | D20: 334 | E20: https://www.youtube.com/watch?v=6hCo4S_1Fhw | F20: 46293 | G20: =FALSE() -> FALSE | H20: 97 | I20: 2188.0515 | J20: 91-180 | K20: 303633 | L20: 0.69900505 | N20: Statement | O20: Science | P20: No | Q20: =FALSE() -> FALSE
A21: Should you rinse your dishes before placing them in the dishwasher? - Rachel Yang | B21: 46191 | C21: 306322 | D21: 305 | E21: https://www.youtube.com/watch?v=FBpBUwlDId0 | F21: 46293 | G21: =FALSE() -> FALSE | H21: 102 | I21: 3003.1569 | J21: 91-180 | K21: 303633 | L21: 1.0088561 | N21: Question | O21: Society | P21: Yes | Q21: =FALSE() -> FALSE
A22: How to attack (and defend) a medieval castle - Connor C. Wilson | B22: 46189 | C22: 303633 | D22: 334 | E22: https://www.youtube.com/watch?v=eR5blcjll8o | F22: 46293 | G22: =FALSE() -> FALSE | H22: 104 | I22: 2919.5481 | J22: 91-180 | K22: 303633 | L22: 1 | N22: Statement | O22: History/Culture | P22: No | Q22: =FALSE() -> FALSE
A23: Meet the slow loris, the only venomous primate in existence - Stephanie A. Poindexter | B23: 46184 | C23: 252082 | D23: 360 | E23: https://www.youtube.com/watch?v=JDqpcHGfJ2I | F23: 46293 | G23: =FALSE() -> FALSE | H23: 109 | I23: 2312.6789 | J23: 91-180 | K23: 303633 | L23: 0.83021938 | N23: Statement | O23: Science | P23: No | Q23: =FALSE() -> FALSE
A24: What is sumo, and why is it so popular? - Lee Thompson | B24: 46182 | C24: 170295 | D24: 338 | E24: https://www.youtube.com/watch?v=Q9Vt6NGBVBc | F24: 46293 | G24: =FALSE() -> FALSE | H24: 111 | I24: 1534.1892 | J24: 91-180 | K24: 303633 | L24: 0.56085801 | N24: Question | O24: History/Culture | P24: No | Q24: =FALSE() -> FALSE
A25: Why does catnip make cats go crazy? - Jaap de Roode | B25: 46177 | C25: 359199 | D25: 300 | E25: https://www.youtube.com/watch?v=HDt_rTPPh70 | F25: 46293 | G25: =FALSE() -> FALSE | H25: 116 | I25: 3096.5431 | J25: 91-180 | K25: 303633 | L25: 1.1830038 | N25: Question | O25: Science | P25: No | Q25: =FALSE() -> FALSE
A26: The dark origins of Disney fairy tales - Claudia Schwabe | B26: 46175 | C26: 538050 | D26: 331 | E26: https://www.youtube.com/watch?v=pyDZpDkU46Y | F26: 46293 | G26: =FALSE() -> FALSE | H26: 118 | I26: 4559.7458 | J26: 91-180 | K26: 303633 | L26: 1.7720406 | N26: Statement | O26: Arts/Language | P26: No | Q26: =FALSE() -> FALSE
A27: Why your best ideas usually start as bad ones | Think Like A Musician | B27: 46170 | C27: 81016 | D27: 293 | E27: https://www.youtube.com/watch?v=BlK23YzqXOM | F27: 46293 | G27: =FALSE() -> FALSE | H27: 123 | I27: 658.66667 | J27: 91-180 | K27: 303633 | L27: 0.26682212 | M27: Underperformer | N27: Statement | O27: Arts/Language | P27: Yes | Q27: =TRUE() -> TRUE
A28: What toys have kids played with throughout history? | B28: 46168 | C28: 3212951 | D28: 322 | E28: https://www.youtube.com/watch?v=aob7rM5PV5A | F28: 46293 | G28: =FALSE() -> FALSE | H28: 125 | I28: 25703.608 | J28: 91-180 | K28: 303633 | L28: 10.581692 | M28: Outlier | N28: Question | O28: History/Culture | P28: No | Q28: =FALSE() -> FALSE
A29: The incredible engineering of Venice - Stephanie H. Smith | B29: 46163 | C29: 180032 | D29: 410 | E29: https://www.youtube.com/watch?v=uBwkMc1llmM | F29: 46293 | G29: =FALSE() -> FALSE | H29: 130 | I29: 1384.8615 | J29: 91-180 | K29: 303633 | L29: 0.59292633 | N29: Statement | O29: History/Culture | P29: No | Q29: =FALSE() -> FALSE
A30: Why is getting bitten by a rabid animal so dangerous? - Charles Rupprecht | B30: 46161 | C30: 965552 | D30: 364 | E30: https://www.youtube.com/watch?v=gePOX4nbMU4 | F30: 46293 | G30: =FALSE() -> FALSE | H30: 132 | I30: 7314.7879 | J30: 91-180 | K30: 303633 | L30: 3.1799969 | M30: Outlier | N30: Question | O30: Health/Psychology | P30: No | Q30: =FALSE() -> FALSE
A31: Edgar Allan Poe's story of the Red Death - Iseult Gillespie | B31: 46156 | C31: 150744 | D31: 426 | E31: https://www.youtube.com/watch?v=HdieAFhQtPo | F31: 46293 | G31: =FALSE() -> FALSE | H31: 137 | I31: 1100.3212 | J31: 91-180 | K31: 303633 | L31: 0.49646778 | M31: Underperformer | N31: Statement | O31: Arts/Language | P31: No | Q31: =FALSE() -> FALSE
A32: The missing ingredient in how we learn | B32: 46154 | C32: 1020612 | D32: 350 | E32: https://www.youtube.com/watch?v=mA1lnxfqHk8 | F32: 46293 | G32: =FALSE() -> FALSE | H32: 139 | I32: 7342.5324 | J32: 91-180 | K32: 303633 | L32: 3.3613342 | M32: Outlier | N32: Statement | O32: Health/Psychology | P32: Yes | Q32: =FALSE() -> FALSE
A33: What to do if you live in the path of a volcano - Arianna Soldati | B33: 46149 | C33: 151609 | D33: 316 | E33: https://www.youtube.com/watch?v=8H--GLt3h8I | F33: 46293 | G33: =FALSE() -> FALSE | H33: 144 | I33: 1052.8403 | J33: 91-180 | K33: 303633 | L33: 0.49931661 | M33: Underperformer | N33: Statement | O33: Science | P33: No | Q33: =FALSE() -> FALSE
A34: How to find hidden clues at crime scenes - Theodore E. Yeshion | B34: 46147 | C34: 198493 | D34: 334 | E34: https://www.youtube.com/watch?v=P8OEz3PvWZQ | F34: 46293 | G34: =FALSE() -> FALSE | H34: 146 | I34: 1359.5411 | J34: 91-180 | K34: 303633 | L34: 0.6537267 | N34: Statement | O34: Society | P34: No | Q34: =FALSE() -> FALSE
A35: The fascinating reason you loved peek-a-boo | B35: 46142 | C35: 1331207 | D35: 329 | E35: https://www.youtube.com/watch?v=qKM4JzToM-A | F35: 46293 | G35: =FALSE() -> FALSE | H35: 151 | I35: 8815.9404 | J35: 91-180 | K35: 303633 | L35: 4.3842632 | M35: Outlier | N35: Statement | O35: Health/Psychology | P35: Yes | Q35: =FALSE() -> FALSE
A36: Why do we use "they" as a singular pronoun? - Arika Okrent | B36: 46140 | C36: 158925 | D36: 334 | E36: https://www.youtube.com/watch?v=65I_1sgTMLE | F36: 46293 | G36: =FALSE() -> FALSE | H36: 153 | I36: 1038.7255 | J36: 91-180 | K36: 303633 | L36: 0.52341149 | N36: Question | O36: Arts/Language | P36: No | Q36: =FALSE() -> FALSE
A37: Write every day, even if it’s terrible | Think Like A Musician | B37: 46135 | C37: 74391 | D37: 361 | E37: https://www.youtube.com/watch?v=2x3rJMBVB28 | F37: 46293 | G37: =FALSE() -> FALSE | H37: 158 | I37: 470.82911 | J37: 91-180 | K37: 303633 | L37: 0.24500301 | M37: Underperformer | N37: Statement | O37: Arts/Language | P37: Yes | Q37: =TRUE() -> TRUE
A38: How can you overcome writer’s block? | B38: 46135 | C38: 38310 | D38: 44 | E38: https://www.youtube.com/watch?v=QRA1-6imP3s | F38: 46293 | G38: =TRUE() -> TRUE | H38: 158 | I38: 242.46835 | J38: 91-180 | N38: Question | O38: Arts/Language | P38: Yes | Q38: =FALSE() -> FALSE
A39: Why was this kung fu masterpiece banned? - Gladys Mac | B39: 46133 | C39: 195973 | D39: 307 | E39: https://www.youtube.com/watch?v=NEFmWclWiOw | F39: 46293 | G39: =FALSE() -> FALSE | H39: 160 | I39: 1224.8312 | J39: 91-180 | K39: 303633 | L39: 0.64542721 | N39: Question | O39: Arts/Language | P39: No | Q39: =FALSE() -> FALSE
A40: Why kids need to take more risks | B40: 46128 | C40: 2054804 | D40: 324 | E40: https://www.youtube.com/watch?v=kRAl4Xgs_NU | F40: 46293 | G40: =FALSE() -> FALSE | H40: 165 | I40: 12453.358 | J40: 91-180 | K40: 303633 | L40: 6.7673935 | M40: Outlier | N40: Statement | O40: Health/Psychology | P40: Yes | Q40: =FALSE() -> FALSE
...

Sheet Pivot Tables
A1: Grouped Performance Summary
A2: All medians are Performance Ratio (video views ÷ median views of same age band). 1.0 = typical for its age.
A4: By Topic Category
A5: Group | B5: Count | C5: Median Ratio | D5: Outliers | E5: Underperformers
A6: Health/Psychology | B6: =COUNTIF(Data!$O$2:$O$94,"Health/Psychology") -> 27 | C6: {=MEDIAN(IF(Data!$O$2:$O$94="Health/Psychology",Data!$L$2:$L$94))} -> 2.3416005 | D6: =COUNTIFS(Data!$O$2:$O$94,"Health/Psychology",Data!$M$2:$M$94,"Outlier") -> 15 | E6: =COUNTIFS(Data!$O$2:$O$94,"Health/Psychology",Data!$M$2:$M$94,"Underperformer") -> 0
A7: Society | B7: =COUNTIF(Data!$O$2:$O$94,"Society") -> 10 | C7: {=MEDIAN(IF(Data!$O$2:$O$94="Society",Data!$L$2:$L$94))} -> 1.0088561 | D7: =COUNTIFS(Data!$O$2:$O$94,"Society",Data!$M$2:$M$94,"Outlier") -> 1 | E7: =COUNTIFS(Data!$O$2:$O$94,"Society",Data!$M$2:$M$94,"Underperformer") -> 0
A8: History/Culture | B8: =COUNTIF(Data!$O$2:$O$94,"History/Culture") -> 19 | C8: {=MEDIAN(IF(Data!$O$2:$O$94="History/Culture",Data!$L$2:$L$94))} -> 1 | D8: =COUNTIFS(Data!$O$2:$O$94,"History/Culture",Data!$M$2:$M$94,"Outlier") -> 2 | E8: =COUNTIFS(Data!$O$2:$O$94,"History/Culture",Data!$M$2:$M$94,"Underperformer") -> 1
A9: Science | B9: =COUNTIF(Data!$O$2:$O$94,"Science") -> 16 | C9: {=MEDIAN(IF(Data!$O$2:$O$94="Science",Data!$L$2:$L$94))} -> 0.85567165 | D9: =COUNTIFS(Data!$O$2:$O$94,"Science",Data!$M$2:$M$94,"Outlier") -> 0 | E9: =COUNTIFS(Data!$O$2:$O$94,"Science",Data!$M$2:$M$94,"Underperformer") -> 3
A10: Arts/Language | B10: =COUNTIF(Data!$O$2:$O$94,"Arts/Language") -> 21 | C10: {=MEDIAN(IF(Data!$O$2:$O$94="Arts/Language",Data!$L$2:$L$94))} -> 0.54554615 | D10: =COUNTIFS(Data!$O$2:$O$94,"Arts/Language",Data!$M$2:$M$94,"Outlier") -> 0 | E10: =COUNTIFS(Data!$O$2:$O$94,"Arts/Language",Data!$M$2:$M$94,"Underperformer") -> 9
A13: By Title Structure
A14: Group | B14: Count | C14: Median Ratio | D14: Outliers | E14: Underperformers
A15: Question | B15: =COUNTIF(Data!$N$2:$N$94,"Question") -> 37 | C15: {=MEDIAN(IF(Data!$N$2:$N$94="Question",Data!$L$2:$L$94))} -> 1.1129482 | D15: =COUNTIFS(Data!$N$2:$N$94,"Question",Data!$M$2:$M$94,"Outlier") -> 9 | E15: =COUNTIFS(Data!$N$2:$N$94,"Question",Data!$M$2:$M$94,"Underperformer") -> 1
A16: Statement | B16: =COUNTIF(Data!$N$2:$N$94,"Statement") -> 51 | C16: {=MEDIAN(IF(Data!$N$2:$N$94="Statement",Data!$L$2:$L$94))} -> 0.9600856 | D16: =COUNTIFS(Data!$N$2:$N$94,"Statement",Data!$M$2:$M$94,"Outlier") -> 7 | E16: =COUNTIFS(Data!$N$2:$N$94,"Statement",Data!$M$2:$M$94,"Underperformer") -> 11
A17: List | B17: =COUNTIF(Data!$N$2:$N$94,"List") -> 5 | C17: {=MEDIAN(IF(Data!$N$2:$N$94="List",Data!$L$2:$L$94))} -> 0.8538268 | D17: =COUNTIFS(Data!$N$2:$N$94,"List",Data!$M$2:$M$94,"Outlier") -> 2 | E17: =COUNTIFS(Data!$N$2:$N$94,"List",Data!$M$2:$M$94,"Underperformer") -> 1
A20: By Everyday Relevance
A21: Group | B21: Count | C21: Median Ratio | D21: Outliers | E21: Underperformers
A22: Yes | B22: =COUNTIF(Data!$P$2:$P$94,"Yes") -> 34 | C22: {=MEDIAN(IF(Data!$P$2:$P$94="Yes",Data!$L$2:$L$94))} -> 1.2322355 | D22: =COUNTIFS(Data!$P$2:$P$94,"Yes",Data!$M$2:$M$94,"Outlier") -> 14 | E22: =COUNTIFS(Data!$P$2:$P$94,"Yes",Data!$M$2:$M$94,"Underperformer") -> 4
A23: No | B23: =COUNTIF(Data!$P$2:$P$94,"No") -> 59 | C23: {=MEDIAN(IF(Data!$P$2:$P$94="No",Data!$L$2:$L$94))} -> 0.85567165 | D23: =COUNTIFS(Data!$P$2:$P$94,"No",Data!$M$2:$M$94,"Outlier") -> 4 | E23: =COUNTIFS(Data!$P$2:$P$94,"No",Data!$M$2:$M$94,"Underperformer") -> 9
A26: Think Like a Musician Series vs. Rest
A27: Group | B27: Count | C27: Median Ratio | D27: Outliers | E27: Underperformers
A28: Series (Think Like a Musician) | B28: =COUNTIF(Data!$Q$2:$Q$94,TRUE()) -> 9 | C28: {=MEDIAN(IF(Data!$Q$2:$Q$94=TRUE(),Data!$L$2:$L$94))} -> 0.26777351 | D28: =COUNTIFS(Data!$Q$2:$Q$94,TRUE(),Data!$M$2:$M$94,"Outlier") -> 0 | E28: =COUNTIFS(Data!$Q$2:$Q$94,TRUE(),Data!$M$2:$M$94,"Underperformer") -> 7
A29: All other videos | B29: =COUNTIF(Data!$Q$2:$Q$94,FALSE()) -> 84 | C29: {=MEDIAN(IF(Data!$Q$2:$Q$94=FALSE(),Data!$L$2:$L$94))} -> 1.0533239 | D29: =COUNTIFS(Data!$Q$2:$Q$94,FALSE(),Data!$M$2:$M$94,"Outlier") -> 18 | E29: =COUNTIFS(Data!$Q$2:$Q$94,FALSE(),Data!$M$2:$M$94,"Underperformer") -> 6

Sheet Notes
A1: Methodology & Limitations
A3: Scope: 93 long-form TED-Ed videos uploaded in the last ~12 months (2 videos under 180 seconds were tagged as Shorts and excluded from band medians). Data pulled via the YouTube Data API v3 and snapshotted on 2026-09-28.
A5: Age-adjustment: Raw view counts favor older videos, which have had more time to accumulate views. Each video is compared only to others uploaded in the same age band (0-30, 31-90, 91-180, 181+ days), using the median views of that band as the baseline. Performance Ratio = video views ÷ its band's median views. 1.0 = typical for its age; 2.0 = twice the typical performance.
A7: Flags: 'Outlier' = ratio ≥ 2.0. 'Underperformer' = ratio ≤ 0.5. These thresholds are a judgment call, not an industry standard.
A9: Tagging: Title structure was assigned by rule (starts with a digit = List; contains '?' = Question; otherwise Statement). Topic category and Everyday Relevance were assigned by manual judgment against a fixed rule set, and are the most subjective part of this analysis.
A11: Limitations: This uses public view counts only — no CTR, impressions, traffic-source, or retention data, which YouTube Studio would provide. Some age bands (especially 0-30 and 31-90 days) have small sample sizes, so their medians should be read as directional, not conclusive. Correlation shown here is not evidence of causation.
A13: Suggested next tests with Studio access: compare CTR and impressions across the outlier vs. typical Health/Psychology videos to see whether the lift comes from packaging or content; check traffic-source split (search vs. suggested vs. browse) on the top 5 outliers; run a retention-curve comparison between the highest- and lowest-ratio videos within the same age band.
